<?xml version="1.0" ?>
<!-- =================================================================================== -->
<!-- |    This document was autogenerated by xacro from irb1200_5_90.xacro             | -->
<!-- |    EDITING THIS FILE BY HAND IS NOT RECOMMENDED                                 | -->
<!-- =================================================================================== -->
<robot name="abb_irb1200_5_90" xmlns:xacro="http://ros.org/wiki/xacro">
  <!-- link list -->
  <link name="base_link">
    <collision name="collision">
      <geometry>
        <mesh filename="D:\VD\Demo\Curobo\ABB-IRB-1200\abb_irb1200_support\meshes\irb1200_5_90\collision\base_link.stl"/>
      </geometry>
    </collision>
    <visual name="visual">
      <geometry>
        <mesh filename="D:\VD\Demo\Curobo\ABB-IRB-1200\abb_irb1200_support\meshes\irb1200_5_90\visual\base_link.dae"/>
      </geometry>
      <material name="yellow">
        <color rgba="1 1 0 1"/>
      </material>
    </visual>
  </link>
  <link name="link_1">
    <collision name="collision">
      <origin rpy="0 0 0" xyz="0 0 0"/>
      <geometry>
        <mesh filename="D:\VD\Demo\Curobo\ABB-IRB-1200\abb_irb1200_support\meshes\irb1200_5_90\collision\link_1.stl"/>
      </geometry>
    </collision>
    <visual name="visual">
      <geometry>
        <mesh filename="D:\VD\Demo\Curobo\ABB-IRB-1200\abb_irb1200_support\meshes\irb1200_5_90\visual\link_1.dae"/>
      </geometry>
      <material name="yellow"/>
    </visual>
  </link>
  <link name="link_2">
    <collision name="collision">
      <origin rpy="0 0 0" xyz="0 0 0"/>
      <geometry>
        <mesh filename="D:\VD\Demo\Curobo\ABB-IRB-1200\abb_irb1200_support\meshes\irb1200_5_90\collision\link_2.stl"/>
      </geometry>
    </collision>
    <visual name="visual">
      <geometry>
        <mesh filename="D:\VD\Demo\Curobo\ABB-IRB-1200\abb_irb1200_support\meshes\irb1200_5_90\visual\link_2.dae"/>
      </geometry>
      <material name="yellow"/>
    </visual>
  </link>
  <link name="link_3">
    <collision name="collision">
      <origin rpy="0 0 0" xyz="0 0 0"/>    
      <geometry>
        <mesh filename="D:\VD\Demo\Curobo\ABB-IRB-1200\abb_irb1200_support\meshes\irb1200_5_90\collision\link_3.stl"/>
      </geometry>
    </collision>
    <visual name="visual">
      <geometry>
        <mesh filename="D:\VD\Demo\Curobo\ABB-IRB-1200\abb_irb1200_support\meshes\irb1200_5_90\visual\link_3.dae"/>
      </geometry>
      <material name="yellow"/>
    </visual>
  </link>
  <link name="link_4">
    <collision name="collision">
      <origin rpy="0 0 0" xyz="0 0 0"/>
      <geometry>
        <mesh filename="D:\VD\Demo\Curobo\ABB-IRB-1200\abb_irb1200_support\meshes\irb1200_5_90\collision\link_4.stl"/>
      </geometry>
    </collision>
    <visual name="visual">
      <geometry>
        <mesh filename="D:\VD\Demo\Curobo\ABB-IRB-1200\abb_irb1200_support\meshes\irb1200_5_90\visual\link_4.dae"/>
      </geometry>
      <material name="yellow"/>
    </visual>
  </link>
  <link name="link_5">
    <collision name="collision">
      <origin rpy="0 0 0" xyz="0 0 0"/>
      <geometry>
        <mesh filename="D:\VD\Demo\Curobo\ABB-IRB-1200\abb_irb1200_support\meshes\irb1200_5_90\collision\link_5.stl"/>
      </geometry>
    </collision>
    <visual name="visual">
      <geometry>
        <mesh filename="D:\VD\Demo\Curobo\ABB-IRB-1200\abb_irb1200_support\meshes\irb1200_5_90\visual\link_5.dae"/>
      </geometry>
      <material name="yellow"/>
    </visual>
  </link>
  <link name="link_6">
    
    <collision name="collision">
      <origin rpy="0 0 0" xyz="0 0 0"/>
      <geometry>
        <mesh filename="D:\VD\Demo\Curobo\ABB-IRB-1200\abb_irb1200_support\meshes\irb1200_5_90\collision\link_6.stl"/>
      </geometry>
    </collision>
    <visual name="visual">
      <geometry>
        <mesh filename="D:\VD\Demo\Curobo\ABB-IRB-1200\abb_irb1200_support\meshes\irb1200_5_90\visual\link_6.dae"/>
      </geometry>
      <material name="yellow"/>
    </visual>
  </link>
  <link name="tool0"/>
  <!-- end of link list -->
  <!-- joint list -->
  <joint name="joint_1" type="revolute">
    <origin rpy="0 0 0" xyz="0 0 0.3991"/>
    <axis xyz="0 0 1"/>
    <parent link="base_link"/>
    <child link="link_1"/>
    <limit effort="0" lower="-2.967" upper="2.967" velocity="5.027"/>
  </joint>
  <joint name="joint_2" type="revolute">
    <origin rpy="0 0 0" xyz="0 0 0"/>
    <axis xyz="0 1 0"/>
    <parent link="link_1"/>
    <child link="link_2"/>
    <limit effort="0" lower="-1.745" upper="2.269" velocity="4.189"/>
  </joint>
  <joint name="joint_3" type="revolute">
    <origin rpy="0 0 0" xyz="0 0 0.448"/>
    <axis xyz="0 1 0"/>
    <parent link="link_2"/>
    <child link="link_3"/>
    <limit effort="0" lower="-3.491" upper="1.222" velocity="5.236"/>
  </joint>
  <joint name="joint_4" type="revolute">
    <origin rpy="0 0 0" xyz="0 0 0.042"/>
    <axis xyz="1 0 0"/>
    <parent link="link_3"/>
    <child link="link_4"/>
    <limit effort="0" lower="-2.0943" upper="2.0943" velocity="6.981"/>
  </joint>
  <joint name="joint_5" type="revolute">
    <origin rpy="0 0 0" xyz="0.451 0 0 "/>
    <axis xyz="0 1 0"/>
    <parent link="link_4"/>
    <child link="link_5"/>
    <limit effort="0" lower="-2.269" upper="2.269" velocity="7.069"/>
  </joint>
  <joint name="joint_6" type="revolute">
    <origin rpy="0 0 0" xyz="0.082 0 0 "/>
    <axis xyz="1 0 0"/>
    <parent link="link_5"/>
    <child link="link_6"/>
    <limit effort="0" lower="-6.283" upper="6.283" velocity="10.472"/>
  </joint>
  <joint name="joint_6-tool0" type="fixed">
    <parent link="link_6"/>
    <child link="tool0"/>
    <origin rpy="0 1.57079632679 0" xyz="0 0 0"/>
  </joint>
  <!-- end of joint list -->
  <!-- ROS base_link to ABB World Coordinates transform -->
  <link name="base"/>
  <joint name="base_link-base" type="fixed">
    <origin rpy="0 0 0" xyz="0 0 0"/>
    <parent link="base_link"/>
    <child link="base"/>
  </joint>


  <joint name="tool0_to_robotiq_base" type="fixed">
    <parent link="tool0"/>
    <child link="robotiq_85_base_link"/>
    <origin xyz="0 0 0.001" rpy="0 0 0"/>
  </joint> 

  <link name="robotiq_85_base_link">
    <inertial>
      <origin xyz="0.00021987 -2.3546E-10 0.030163" rpy="0 0 0"/>
      <mass value="0.30915"/>
      <inertia
        ixx="0.00028972"
        ixy="-5.7879E-10"
        ixz="-1.8543E-06"
        iyy="0.00030737"
        iyz="1.682E-12"
        izz="0.00019914"/>
    </inertial>
    <visual>
      <origin xyz="0 0 0" rpy="0 0 0"/>
      <geometry>
        <mesh filename="D:\VD\Demo\Curobo\gripper\mesh\robotiq_85_base_link_fine.STL"/>
      </geometry>
      <material name="">
        <color rgba="0.1 0.1 0.1 1"/>
      </material>
    </visual>
    <collision>
      <origin xyz="0 0 0" rpy="0 0 0"/>
      <geometry>
        <mesh filename="D:\VD\Demo\Curobo\gripper\mesh\robotiq_85_base_link_coarse.STL"/>
      </geometry>
    </collision>
  </link>

  <joint name="robotiq_tcp_joint" type="fixed">
    <parent link="robotiq_85_base_link"/>
    <child link="robotiq_tcp"/>
    <origin xyz="0 0 0.16" rpy="0 0 0"/>
  </joint>

  <link name="robotiq_tcp"/>
  <link name="left_outer_knuckle">
    <inertial>
      <origin xyz="0.0178331863169983 3.68915177224286E-11 0.0021442477325704" rpy="0 0 0"/>
      <mass value="0.00684838849434396"/>
      <inertia
        ixx="2.66832029033166E-07"
        ixy="1.66142314639824E-15"
        ixz="1.45945633322873E-07"
        iyy="1.3889233257419E-06"
        iyz="2.82951161241588E-15"
        izz="1.26603336914415E-06"/>
    </inertial>
    <visual>
      <origin xyz="0 0 0" rpy="0 0 0"/>
      <geometry>
        <mesh filename="D:\VD\Demo\Curobo\gripper\mesh\outer_knuckle_fine.STL"/>
      </geometry>
      <material name="">
        <color rgba="0.1 0.1 0.1 1"/>
      </material>
    </visual>
    <collision>
      <origin xyz="0 0 0" rpy="0 0 0"/>
      <geometry>
        <mesh filename="D:\VD\Demo\Curobo\gripper\mesh\outer_knuckle_coarse.STL"/>
      </geometry>
    </collision>
  </link>

  <joint name="finger_joint_fixed" type="fixed">
    <origin xyz="0.0306011444260539 0 0.0627920162695395" rpy="0 0 0"/>
    <parent link="robotiq_85_base_link"/>
    <child link="left_outer_knuckle"/>
  </joint>

  <link name="left_outer_finger">
    <inertial>
      <origin xyz="0.00131451599174296 2.88942057994543E-15 0.0215404163180413" rpy="0 0 0"/>
      <mass value="0.0273093985570947"/>
      <inertia
        ixx="8.51629628283022E-06"
        ixy="2.58174336207405E-19"
        ixz="3.83829504344079E-07"
        iyy="6.9133328065108E-06"
        iyz="-7.58589926143789E-19"
        izz="2.25006832221981E-06"/>
    </inertial>
    <visual>
      <origin xyz="0 0 0" rpy="0 0 0"/>
      <geometry>
        <mesh filename="D:\VD\Demo\Curobo\gripper\mesh\outer_finger_fine.STL"/>
      </geometry>
      <material name="">
        <color rgba="0.1 0.1 0.1 1"/>
      </material>
    </visual>
    <collision>
      <origin xyz="0 0 0" rpy="0 0 0"/>
      <geometry>
        <mesh filename="D:\VD\Demo\Curobo\gripper\mesh\outer_finger_coarse.STL"/>
      </geometry>
    </collision>
  </link>

  <joint name="left_outer_finger_joint" type="fixed">
    <origin xyz="0.0316910442266543 0 -0.00193396375724605" rpy="0 0 0"/>
    <parent link="left_outer_knuckle"/>
    <child link="left_outer_finger"/>
  </joint>

  <link name="left_inner_knuckle">
    <inertial>
      <origin xyz="0.017097546626628 -3.93808524389535E-10 0.0224918438201868" rpy="0 0 0"/>
      <mass value="0.0110930853895903"/>
      <inertia
        ixx="4.23392770691541E-06"
        ixy="5.748978936968E-15"
        ixz="1.78855677119788E-06"
        iyy="3.96548790524392E-06"
        iyz="1.05464666369669E-14"
        izz="3.24068002883007E-06"/>
    </inertial>
    <visual>
      <origin xyz="0 0 0" rpy="0 0 0"/>
      <geometry>
        <mesh filename="D:\VD\Demo\Curobo\gripper\mesh\inner_knuckle_fine.STL"/>
      </geometry>
      <material name="">
        <color rgba="0.1 0.1 0.1 1"/>
      </material>
    </visual>
    <collision>
      <origin xyz="0 0 0" rpy="0 0 0"/>
      <geometry>
        <mesh filename="D:\VD\Demo\Curobo\gripper\mesh\inner_knuckle_coarse.STL"/>
      </geometry>
    </collision>
  </link>

  <joint name="left_inner_knuckle_joint_fixed" type="fixed">
    <origin xyz="0.0127000000001501 0 0.0693074999999639" rpy="0 0 0"/>
    <parent link="robotiq_85_base_link"/>
    <child link="left_inner_knuckle"/>
  </joint>

  <link name="left_inner_finger">
    <inertial>
      <origin xyz="0.0060275613594574 -6.29183141465421E-15 0.00669925693133241" rpy="0 0 0"/>
      <mass value="0.00724255346165745"/>
      <inertia
        ixx="1.47824274053603E-06"
        ixy="-3.94884463570303E-19"
        ixz="-3.45268847648622E-07"
        iyy="1.70064480838395E-06"
        iyz="3.5059838910097E-19"
        izz="4.77151336838364E-07"/>
    </inertial>
    <visual>
      <origin xyz="0 0 0" rpy="0 0 0"/>
      <geometry>
        <mesh filename="D:\VD\Demo\Curobo\gripper\mesh\inner_finger_fine.STL"/>
      </geometry>
      <material name="">
        <color rgba="0.1 0.1 0.1 1"/>
      </material>
    </visual>
    <collision>
      <origin xyz="0 0 0" rpy="0 0 0"/>
      <geometry>
        <mesh filename="D:\VD\Demo\Curobo\gripper\mesh\inner_finger_coarse.STL"/>
      </geometry>
    </collision>
  </link>

  <joint name="left_inner_finger_joint_fixed" type="fixed">
    <origin xyz="0.034585310861294 0 0.0454970193817975" rpy="0 0 0"/>
    <parent link="left_inner_knuckle"/>
    <child link="left_inner_finger"/>
  </joint>

  <link name="right_inner_knuckle">
    <inertial>
      <origin xyz="0.0168606186773776 3.93808471820465E-10 0.0226699950793434" rpy="0 0 0"/>
      <mass value="0.0110930853895903"/>
      <inertia
        ixx="4.27134775939882E-06"
        ixy="-8.53568456728898E-15"
        ixz="1.77774229944246E-06"
        iyy="3.96548790524392E-06"
        iyz="-8.45108024914164E-15"
        izz="3.20325997634666E-06"/>
    </inertial>
    <visual>
      <origin xyz="0 0 0" rpy="0 0 0"/>
      <geometry>
        <mesh filename="D:\VD\Demo\Curobo\gripper\mesh\inner_knuckle_fine.STL"/>
      </geometry>
      <material name="">
        <color rgba="0.1 0.1 0.1 1"/>
      </material>
    </visual>
    <collision>
      <origin xyz="0 0 0" rpy="0 0 0"/>
      <geometry>
        <mesh filename="D:\VD\Demo\Curobo\gripper\mesh\inner_knuckle_coarse.STL"/>
      </geometry>
    </collision>
  </link>

  <joint name="right_inner_knuckle_joint_fixed" type="fixed">
    <origin xyz="-0.0126999999998499 0 0.0693075000000361" rpy="0 0 3.14159265358979"/>
    <parent link="robotiq_85_base_link"/>
    <child link="right_inner_knuckle"/>
  </joint>

  <link name="right_inner_finger">
    <inertial>
      <origin xyz="0.00602756228812038 -6.47284509480176E-15 0.00669925609578108" rpy="0 0 0"/>
      <mass value="0.00724255346165744"/>
      <inertia
        ixx="1.47824283625957E-06"
        ixy="-3.95952064019123E-19"
        ixz="-3.45268708875543E-07"
        iyy="1.70064480838394E-06"
        iyz="3.55286507960029E-19"
        izz="4.77151241114822E-07"/>
    </inertial>
    <visual>
      <origin xyz="0 0 0" rpy="0 0 0"/>
      <geometry>
        <mesh filename="D:\VD\Demo\Curobo\gripper\mesh\inner_finger_fine.STL"/>
      </geometry>
      <material name="">
        <color rgba="0.1 0.1 0.1 1"/>
      </material>
    </visual>
    <collision>
      <origin xyz="0 0 0" rpy="0 0 0"/>
      <geometry>
        <mesh filename="D:\VD\Demo\Curobo\gripper\mesh\inner_finger_coarse.STL"/>
      </geometry>
    </collision>
  </link>

  <joint name="right_inner_finger_joint_fixed" type="fixed">
    <origin xyz="0.0341060475457406 0 0.0458573878541688" rpy="0 0 0"/>
    <parent link="right_inner_knuckle"/>
    <child link="right_inner_finger"/>
  </joint>

  <link name="right_outer_knuckle">
    <inertial>
      <origin xyz="0.0178097074051638 3.60493211424024E-11 0.00233123458346721" rpy="0 0 0"/>
      <mass value="0.00684838849401352"/>
      <inertia
        ixx="2.70004361573169E-07"
        ixy="1.59579467624491E-15"
        ixz="1.56396493788199E-07"
        iyy="1.38892332558312E-06"
        iyz="2.82357800318817E-15"
        izz="1.26286103637978E-06"/>
    </inertial>
    <visual>
      <origin xyz="0 0 0" rpy="0 0 0"/>
      <geometry>
        <mesh filename="D:\VD\Demo\Curobo\gripper\mesh\outer_knuckle_fine.STL"/>
      </geometry>
      <material name="">
        <color rgba="0.1 0.1 0.1 1"/>
      </material>
    </visual>
    <collision>
      <origin xyz="0 0 0" rpy="0 0 0"/>
      <geometry>
        <mesh filename="D:\VD\Demo\Curobo\gripper\mesh\outer_knuckle_coarse.STL"/>
      </geometry>
    </collision>
  </link>

  <joint name="right_outer_knuckle_joint_fixed" type="fixed">
    <origin xyz="-0.0306011444258893 0 0.0627920162695395" rpy="0 0 3.14159265358979"/>
    <parent link="robotiq_85_base_link"/>
    <child link="right_outer_knuckle"/>
  </joint>

  <link name="right_outer_finger">
    <inertial>
      <origin xyz="0.00108844269639009 -2.611488350845E-15 0.0215530225245502" rpy="0 0 0"/>
      <mass value="0.0273093985570947"/>
      <inertia
        ixx="8.52366028592721E-06"
        ixy="3.41683380899422E-19"
        ixz="3.18003675694284E-07"
        iyy="6.91333280651081E-06"
        iyz="7.37726682706417E-19"
        izz="2.24270431912283E-06"/>
    </inertial>
    <visual>
      <origin xyz="0 0 0" rpy="0 0 0"/>
      <geometry>
        <mesh filename="D:\VD\Demo\Curobo\gripper\mesh\outer_finger_fine.STL"/>
      </geometry>
      <material name="">
        <color rgba="0.1 0.1 0.1 1"/>
      </material>
    </visual>
    <collision>
      <origin xyz="0 0 0" rpy="0 0 0"/>
      <geometry>
        <mesh filename="D:\VD\Demo\Curobo\gripper\mesh\outer_finger_coarse.STL"/>
      </geometry>
    </collision>
  </link>

  <joint name="right_outer_finger_joint" type="fixed">
    <origin xyz="0.0317095909367246 0 -0.0016013564954687" rpy="0 0 0"/>
    <parent link="right_outer_knuckle"/>
    <child link="right_outer_finger"/>
  </joint>
  
</robot>